Traceback (most recent call last):
  File "/Users/mcburton/opt/anaconda3/lib/python3.9/site-packages/jupyter_cache/executors/utils.py", line 51, in single_nb_execution
    executenb(
  File "/Users/mcburton/opt/anaconda3/lib/python3.9/site-packages/nbclient/client.py", line 1204, in execute
    return NotebookClient(nb=nb, resources=resources, km=km, **kwargs).execute()
  File "/Users/mcburton/opt/anaconda3/lib/python3.9/site-packages/nbclient/util.py", line 84, in wrapped
    return just_run(coro(*args, **kwargs))
  File "/Users/mcburton/opt/anaconda3/lib/python3.9/site-packages/nbclient/util.py", line 62, in just_run
    return loop.run_until_complete(coro)
  File "/Users/mcburton/opt/anaconda3/lib/python3.9/asyncio/base_events.py", line 647, in run_until_complete
    return future.result()
  File "/Users/mcburton/opt/anaconda3/lib/python3.9/site-packages/nbclient/client.py", line 663, in async_execute
    await self.async_execute_cell(
  File "/Users/mcburton/opt/anaconda3/lib/python3.9/site-packages/nbclient/client.py", line 965, in async_execute_cell
    await self._check_raise_for_error(cell, cell_index, exec_reply)
  File "/Users/mcburton/opt/anaconda3/lib/python3.9/site-packages/nbclient/client.py", line 862, in _check_raise_for_error
    raise CellExecutionError.from_cell_and_msg(cell, exec_reply_content)
nbclient.exceptions.CellExecutionError: An error occurred while executing the following cell:
------------------
# Load up the CSV module
import csv

# open a file hander
file_handler = open('community-center-attendance.csv')
# Load the file into the CSV module
reader = csv.reader(file_handler)

# read the headers first
headers = next(reader)

# Read all the data into a variable as a list. look ma! one line!
center_attendance_python = [row for row in reader]

# close the file handler for good hygiene 
file_handler.close()

# print headesr
print(headers)

# display the first five rows 
center_attendance_python[0:5]
------------------

[0;31m---------------------------------------------------------------------------[0m
[0;31mFileNotFoundError[0m                         Traceback (most recent call last)
Input [0;32mIn [3][0m, in [0;36m<cell line: 5>[0;34m()[0m
[1;32m      2[0m [38;5;28;01mimport[39;00m [38;5;21;01mcsv[39;00m
[1;32m      4[0m [38;5;66;03m# open a file hander[39;00m
[0;32m----> 5[0m file_handler [38;5;241m=[39m [38;5;28;43mopen[39;49m[43m([49m[38;5;124;43m'[39;49m[38;5;124;43mcommunity-center-attendance.csv[39;49m[38;5;124;43m'[39;49m[43m)[49m
[1;32m      6[0m [38;5;66;03m# Load the file into the CSV module[39;00m
[1;32m      7[0m reader [38;5;241m=[39m csv[38;5;241m.[39mreader(file_handler)

[0;31mFileNotFoundError[0m: [Errno 2] No such file or directory: 'community-center-attendance.csv'
FileNotFoundError: [Errno 2] No such file or directory: 'community-center-attendance.csv'

